<?xml version="1.0" ?>
<!-- =================================================================================== -->
<!-- |    This document was autogenerated by xacro from assets/flexy_arm.xacro         | -->
<!-- |    EDITING THIS FILE BY HAND IS NOT RECOMMENDED                                 | -->
<!-- =================================================================================== -->
<robot name="flexy_arm">
  <!-- Create the base link -->
  <link name="arm_base"/>
  <link name="arm_link_1">
    <visual>
      <geometry>
        <mesh filename="meshes/single_segment.dae" scale="0.0006 0.0006 0.00030000000000000003"/>
      </geometry>
      <origin xyz="0 0 0.015"/>
    </visual>
    <collision>
      <geometry>
        <cylinder length="0.03" radius="0.01"/>
      </geometry>
      <origin xyz="0 0 0.015"/>
    </collision>
    <inertial>
      <mass value="0.09090909090909091"/>
      <inertia ixx="9.090909090909091e-06" ixy="0.0" ixz="0.0" iyy="9.090909090909091e-06" iyz="0.0" izz="4.5454545454545455e-06"/>
    </inertial>
  </link>
  <joint name="arm_joint_1" type="revolute">
    <parent link="arm_base"/>
    <child link="arm_link_1"/>
    <axis xyz="1 0 0"/>
    <origin rpy="0.0 0.0 1.57079" xyz=" 0.0 0.0 0.0"/>
    <limit effort="10.0" lower="-1.57" upper="1.57" velocity="1.0"/>
  </joint>
  <!-- Create the next link -->
  <link name="arm_link_2">
    <visual>
      <geometry>
        <mesh filename="meshes/single_segment.dae" scale="0.0006 0.0006 0.00030000000000000003"/>
      </geometry>
      <origin xyz="0 0 0.015"/>
    </visual>
    <collision>
      <geometry>
        <cylinder length="0.03" radius="0.01"/>
      </geometry>
      <origin xyz="0 0 0.015"/>
    </collision>
    <inertial>
      <mass value="0.09090909090909091"/>
      <inertia ixx="9.090909090909091e-06" ixy="0.0" ixz="0.0" iyy="9.090909090909091e-06" iyz="0.0" izz="4.5454545454545455e-06"/>
    </inertial>
  </link>
  <!-- Create the revolute joint -->
  <joint name="arm_joint_2" type="revolute">
    <parent link="arm_link_1"/>
    <child link="arm_link_2"/>
    <axis xyz="1 0 0"/>
    <origin rpy="0 0 0" xyz="0 0 0.03"/>
    <limit effort="10.0" lower="-1.57" upper="1.57" velocity="1.0"/>
  </joint>
  <!-- Create the next link -->
  <link name="arm_link_3">
    <visual>
      <geometry>
        <mesh filename="meshes/single_segment.dae" scale="0.0006 0.0006 0.00030000000000000003"/>
      </geometry>
      <origin xyz="0 0 0.015"/>
    </visual>
    <collision>
      <geometry>
        <cylinder length="0.03" radius="0.01"/>
      </geometry>
      <origin xyz="0 0 0.015"/>
    </collision>
    <inertial>
      <mass value="0.09090909090909091"/>
      <inertia ixx="9.090909090909091e-06" ixy="0.0" ixz="0.0" iyy="9.090909090909091e-06" iyz="0.0" izz="4.5454545454545455e-06"/>
    </inertial>
  </link>
  <!-- Create the revolute joint -->
  <joint name="arm_joint_3" type="revolute">
    <parent link="arm_link_2"/>
    <child link="arm_link_3"/>
    <axis xyz="1 0 0"/>
    <origin rpy="0 0 0" xyz="0 0 0.03"/>
    <limit effort="10.0" lower="-1.57" upper="1.57" velocity="1.0"/>
  </joint>
  <!-- Create the next link -->
  <link name="arm_link_4">
    <visual>
      <geometry>
        <mesh filename="meshes/single_segment.dae" scale="0.0006 0.0006 0.00030000000000000003"/>
      </geometry>
      <origin xyz="0 0 0.015"/>
    </visual>
    <collision>
      <geometry>
        <cylinder length="0.03" radius="0.01"/>
      </geometry>
      <origin xyz="0 0 0.015"/>
    </collision>
    <inertial>
      <mass value="0.09090909090909091"/>
      <inertia ixx="9.090909090909091e-06" ixy="0.0" ixz="0.0" iyy="9.090909090909091e-06" iyz="0.0" izz="4.5454545454545455e-06"/>
    </inertial>
  </link>
  <!-- Create the revolute joint -->
  <joint name="arm_joint_4" type="revolute">
    <parent link="arm_link_3"/>
    <child link="arm_link_4"/>
    <axis xyz="1 0 0"/>
    <origin rpy="0 0 0" xyz="0 0 0.03"/>
    <limit effort="10.0" lower="-1.57" upper="1.57" velocity="1.0"/>
  </joint>
  <!-- Create the next link -->
  <link name="arm_link_5">
    <visual>
      <geometry>
        <mesh filename="meshes/single_segment.dae" scale="0.0006 0.0006 0.00030000000000000003"/>
      </geometry>
      <origin xyz="0 0 0.015"/>
    </visual>
    <collision>
      <geometry>
        <cylinder length="0.03" radius="0.01"/>
      </geometry>
      <origin xyz="0 0 0.015"/>
    </collision>
    <inertial>
      <mass value="0.09090909090909091"/>
      <inertia ixx="9.090909090909091e-06" ixy="0.0" ixz="0.0" iyy="9.090909090909091e-06" iyz="0.0" izz="4.5454545454545455e-06"/>
    </inertial>
  </link>
  <!-- Create the revolute joint -->
  <joint name="arm_joint_5" type="revolute">
    <parent link="arm_link_4"/>
    <child link="arm_link_5"/>
    <axis xyz="1 0 0"/>
    <origin rpy="0 0 0" xyz="0 0 0.03"/>
    <limit effort="10.0" lower="-1.57" upper="1.57" velocity="1.0"/>
  </joint>
  <!-- Create the next link -->
  <link name="arm_link_6">
    <visual>
      <geometry>
        <mesh filename="meshes/single_segment.dae" scale="0.0006 0.0006 0.00030000000000000003"/>
      </geometry>
      <origin xyz="0 0 0.015"/>
    </visual>
    <collision>
      <geometry>
        <cylinder length="0.03" radius="0.01"/>
      </geometry>
      <origin xyz="0 0 0.015"/>
    </collision>
    <inertial>
      <mass value="0.09090909090909091"/>
      <inertia ixx="9.090909090909091e-06" ixy="0.0" ixz="0.0" iyy="9.090909090909091e-06" iyz="0.0" izz="4.5454545454545455e-06"/>
    </inertial>
  </link>
  <!-- Create the revolute joint -->
  <joint name="arm_joint_6" type="revolute">
    <parent link="arm_link_5"/>
    <child link="arm_link_6"/>
    <axis xyz="1 0 0"/>
    <origin rpy="0 0 0" xyz="0 0 0.03"/>
    <limit effort="10.0" lower="-1.57" upper="1.57" velocity="1.0"/>
  </joint>
  <!-- Create the next link -->
  <link name="arm_link_7">
    <visual>
      <geometry>
        <mesh filename="meshes/single_segment.dae" scale="0.0006 0.0006 0.00030000000000000003"/>
      </geometry>
      <origin xyz="0 0 0.015"/>
    </visual>
    <collision>
      <geometry>
        <cylinder length="0.03" radius="0.01"/>
      </geometry>
      <origin xyz="0 0 0.015"/>
    </collision>
    <inertial>
      <mass value="0.09090909090909091"/>
      <inertia ixx="9.090909090909091e-06" ixy="0.0" ixz="0.0" iyy="9.090909090909091e-06" iyz="0.0" izz="4.5454545454545455e-06"/>
    </inertial>
  </link>
  <!-- Create the revolute joint -->
  <joint name="arm_joint_7" type="revolute">
    <parent link="arm_link_6"/>
    <child link="arm_link_7"/>
    <axis xyz="1 0 0"/>
    <origin rpy="0 0 0" xyz="0 0 0.03"/>
    <limit effort="10.0" lower="-1.57" upper="1.57" velocity="1.0"/>
  </joint>
  <!-- Create the next link -->
  <link name="arm_link_8">
    <visual>
      <geometry>
        <mesh filename="meshes/single_segment.dae" scale="0.0006 0.0006 0.00030000000000000003"/>
      </geometry>
      <origin xyz="0 0 0.015"/>
    </visual>
    <collision>
      <geometry>
        <cylinder length="0.03" radius="0.01"/>
      </geometry>
      <origin xyz="0 0 0.015"/>
    </collision>
    <inertial>
      <mass value="0.09090909090909091"/>
      <inertia ixx="9.090909090909091e-06" ixy="0.0" ixz="0.0" iyy="9.090909090909091e-06" iyz="0.0" izz="4.5454545454545455e-06"/>
    </inertial>
  </link>
  <!-- Create the revolute joint -->
  <joint name="arm_joint_8" type="revolute">
    <parent link="arm_link_7"/>
    <child link="arm_link_8"/>
    <axis xyz="1 0 0"/>
    <origin rpy="0 0 0" xyz="0 0 0.03"/>
    <limit effort="10.0" lower="-1.57" upper="1.57" velocity="1.0"/>
  </joint>
  <!-- Create the next link -->
  <link name="arm_link_9">
    <visual>
      <geometry>
        <mesh filename="meshes/single_segment.dae" scale="0.0006 0.0006 0.00030000000000000003"/>
      </geometry>
      <origin xyz="0 0 0.015"/>
    </visual>
    <collision>
      <geometry>
        <cylinder length="0.03" radius="0.01"/>
      </geometry>
      <origin xyz="0 0 0.015"/>
    </collision>
    <inertial>
      <mass value="0.09090909090909091"/>
      <inertia ixx="9.090909090909091e-06" ixy="0.0" ixz="0.0" iyy="9.090909090909091e-06" iyz="0.0" izz="4.5454545454545455e-06"/>
    </inertial>
  </link>
  <!-- Create the revolute joint -->
  <joint name="arm_joint_9" type="revolute">
    <parent link="arm_link_8"/>
    <child link="arm_link_9"/>
    <axis xyz="1 0 0"/>
    <origin rpy="0 0 0" xyz="0 0 0.03"/>
    <limit effort="10.0" lower="-1.57" upper="1.57" velocity="1.0"/>
  </joint>
  <!-- Create the next link -->
  <link name="arm_link_10">
    <visual>
      <geometry>
        <mesh filename="meshes/single_segment.dae" scale="0.0006 0.0006 0.00030000000000000003"/>
      </geometry>
      <origin xyz="0 0 0.015"/>
    </visual>
    <collision>
      <geometry>
        <cylinder length="0.03" radius="0.01"/>
      </geometry>
      <origin xyz="0 0 0.015"/>
    </collision>
    <inertial>
      <mass value="0.09090909090909091"/>
      <inertia ixx="9.090909090909091e-06" ixy="0.0" ixz="0.0" iyy="9.090909090909091e-06" iyz="0.0" izz="4.5454545454545455e-06"/>
    </inertial>
  </link>
  <!-- Create the revolute joint -->
  <joint name="arm_joint_10" type="revolute">
    <parent link="arm_link_9"/>
    <child link="arm_link_10"/>
    <axis xyz="1 0 0"/>
    <origin rpy="0 0 0" xyz="0 0 0.03"/>
    <limit effort="10.0" lower="-1.57" upper="1.57" velocity="1.0"/>
  </joint>
  <link name="arm_sphere">
    <visual>
      <geometry>
        <sphere radius="0.01"/>
      </geometry>
      <origin xyz="0 0 0.01"/>
    </visual>
    <collision>
      <geometry>
        <sphere radius="0.01"/>
      </geometry>
      <origin xyz="0 0 0.01"/>
    </collision>
    <inertial>
      <mass value="0.09090909090909091"/>
      <inertia ixx="3.6363636363636366e-06" ixy="0.0" ixz="0.0" iyy="3.6363636363636366e-06" iyz="0.0" izz="3.6363636363636366e-06"/>
    </inertial>
  </link>
  <joint name="arm_fixed_joint_sphere" type="fixed">
    <parent link="arm_link_10"/>
    <child link="arm_sphere"/>
    <origin rpy="0 0 0" xyz="0 0 0.019999999999999997"/>
  </joint>
</robot>
