<?xml version="1.0"?>
<robot name="pendulum_with_heavy_base">
  <!-- Fixed base -->
  <link name="base_link"/>
   
  <!-- Pendulum link -->
  <link name="pendulum_link">
    <inertial>
      <origin xyz="0 0 -0.5" rpy="0 0 0"/>
      <mass value="0.0"/>
      <inertia ixx="0.00" ixy="0" ixz="0" iyy="0.00" iyz="0" izz="0.00"/>
    </inertial>
    <visual>
      <origin xyz="0 0 -0.5" rpy="0 0 0"/>
      <geometry>
        <cylinder length="1.0" radius="0.05"/>
      </geometry>
      <material name="blue">
        <color rgba="0 0 1 1"/>
      </material>
    </visual>
    <collision>
      <origin xyz="0 0 -0.5" rpy="0 0 0"/>
      <geometry>
        <cylinder length="1.0" radius="0.05"/>
      </geometry>
    </collision>
  </link>

  <!-- Additional mass at the end of the pendulum -->
  <link name="end_mass">
    <inertial>
      <origin xyz="0 0 -0.5" rpy="0 0 0"/>
      <mass value="1.0"/>
      <origin xyz="0 0 -1.0"/>
      <inertia ixx="0.02" ixy="0" ixz="0" iyy="0.02" iyz="0" izz="0.02"/>
    </inertial>
    <visual>
      <origin xyz="0 0 -0.5" rpy="0 0 0"/>
      <geometry>
        <sphere radius="0.1"/>
      </geometry>
      <material name="red">
        <color rgba="1 0 0 1"/>
      </material>
    </visual>
    <collision>
      <origin xyz="0 0 -0.5" rpy="0 0 0"/>
      <geometry>
        <sphere radius="0.1"/>
      </geometry>
    </collision>
  </link>

  <!-- Joint between base and pendulum -->
  <joint name="continuous_joint" type="continuous">
    <parent link="base_link"/>
    <child link="pendulum_link"/>
    <axis xyz="0 1 0"/>
    <origin xyz="0 0 0" rpy="3.14169 0 0"/>
    <limit lower="-6.28" upper="6.28" effort="1000.0" velocity="100.0"/>
  </joint>

  <!-- Fixed joint for additional mass -->
  <joint name="fixed_joint" type="fixed">
    <parent link="pendulum_link"/>
    <child link="end_mass"/>
    <origin xyz="0 0 -0.5" rpy="0 0 0"/>
  </joint>
</robot>
